[BUG]: Command '['C:\\Users\\Administrator\\AppData\\Local\\Programs\\Python\\Python312\\python.exe', '-m', 'PyInstaller', '--clean', '--distpath', 'dist', '--workpath', '.pyarmor\\pack\\build', '.\\wxdump.patched.spec']' returned non-zero exit status 3221225478.

## Command Line
C:\Users\Administrator\AppData\Local\Programs\Python\Python312\Scripts\pyarmor gen --pack .\wxdump.spec -r .\pywxdump\cli.py

## Environments
Python 3.12.8
Pyarmor 9.1.3 (trial), 000000, non-profits
Platform windows.x86_64
Native windows.amd64
Home C:\Users\Administrator\.pyarmor

## Traceback
Traceback (most recent call last):
  File "C:\Users\Administrator\AppData\Local\Programs\Python\Python312\Lib\site-packages\pyarmor\cli\__main__.py", line 793, in main
    main_entry(sys.argv[1:])
  File "C:\Users\Administrator\AppData\Local\Programs\Python\Python312\Lib\site-packages\pyarmor\cli\__main__.py", line 786, in main_entry
    return args.func(ctx, args)
           ^^^^^^^^^^^^^^^^^^^^
  File "C:\Users\Administrator\AppData\Local\Programs\Python\Python312\Lib\site-packages\pyarmor\cli\__main__.py", line 246, in cmd_gen
    packer.build()
  File "C:\Users\Administrator\AppData\Local\Programs\Python\Python312\Lib\site-packages\pyarmor\cli\repack.py", line 338, in build
    check_call(cmdlist)
  File "C:\Users\Administrator\AppData\Local\Programs\Python\Python312\Lib\subprocess.py", line 413, in check_call
    raise CalledProcessError(retcode, cmd)
subprocess.CalledProcessError: Command '['C:\\Users\\Administrator\\AppData\\Local\\Programs\\Python\\Python312\\python.exe', '-m', 'PyInstaller', '--clean', '--distpath', 'dist', '--workpath', '.pyarmor\\pack\\build', '.\\wxdump.patched.spec']' returned non-zero exit status 3221225478.


